2018-10-03 18:31:09,749 INFO: Microblog startup [in /home/v1b3m/flask/microblog/app/__init__.py:47]
2018-10-03 18:31:48,586 ERROR: Exception on /reset_password/eyJ0eXAiOiJKV1QiLCJhbGciOiJIUzI1NiJ9.eyJyZXNldF9wYXNzd29yZCI6MTAsImV4cCI6MTUzODU4MTI3NC42OTUzNzN9.lUW0wRmDeLXUxtGArJRqcQd9beHs_ciHB33lZQMqaP4 [GET] [in /home/v1b3m/flask/microblog/venv/lib/python3.6/site-packages/flask/app.py:1761]
Traceback (most recent call last):
  File "/home/v1b3m/flask/microblog/venv/lib/python3.6/site-packages/flask/app.py", line 2292, in wsgi_app
    response = self.full_dispatch_request()
  File "/home/v1b3m/flask/microblog/venv/lib/python3.6/site-packages/flask/app.py", line 1815, in full_dispatch_request
    rv = self.handle_user_exception(e)
  File "/home/v1b3m/flask/microblog/venv/lib/python3.6/site-packages/flask/app.py", line 1718, in handle_user_exception
    reraise(exc_type, exc_value, tb)
  File "/home/v1b3m/flask/microblog/venv/lib/python3.6/site-packages/flask/_compat.py", line 35, in reraise
    raise value
  File "/home/v1b3m/flask/microblog/venv/lib/python3.6/site-packages/flask/app.py", line 1813, in full_dispatch_request
    rv = self.dispatch_request()
  File "/home/v1b3m/flask/microblog/venv/lib/python3.6/site-packages/flask/app.py", line 1799, in dispatch_request
    return self.view_functions[rule.endpoint](**req.view_args)
  File "/home/v1b3m/flask/microblog/app/routes.py", line 170, in reset_password
    form = ResetPasswordForm()
  File "/home/v1b3m/flask/microblog/venv/lib/python3.6/site-packages/wtforms/form.py", line 212, in __call__
    return type.__call__(cls, *args, **kwargs)
  File "/home/v1b3m/flask/microblog/venv/lib/python3.6/site-packages/flask_wtf/form.py", line 88, in __init__
    super(FlaskForm, self).__init__(formdata=formdata, **kwargs)
  File "/home/v1b3m/flask/microblog/venv/lib/python3.6/site-packages/wtforms/form.py", line 272, in __init__
    super(Form, self).__init__(self._unbound_fields, meta=meta_obj, prefix=prefix)
  File "/home/v1b3m/flask/microblog/venv/lib/python3.6/site-packages/wtforms/form.py", line 52, in __init__
    field = meta.bind_field(self, unbound_field, options)
  File "/home/v1b3m/flask/microblog/venv/lib/python3.6/site-packages/wtforms/meta.py", line 27, in bind_field
    return unbound_field.bind(form=form, **options)
  File "/home/v1b3m/flask/microblog/venv/lib/python3.6/site-packages/wtforms/fields/core.py", line 353, in bind
    return self.field_class(*self.args, **kw)
TypeError: __init__() got an unexpected keyword argument 'vaidators'
2018-10-03 18:33:08,355 INFO: Microblog startup [in /home/v1b3m/flask/microblog/app/__init__.py:47]
2018-10-03 18:40:20,453 INFO: Microblog startup [in /home/v1b3m/flask/microblog/app/__init__.py:47]
2018-10-03 18:40:42,777 ERROR: Exception on /reset_password_request [POST] [in /home/v1b3m/flask/microblog/venv/lib/python3.6/site-packages/flask/app.py:1761]
Traceback (most recent call last):
  File "/home/v1b3m/flask/microblog/venv/lib/python3.6/site-packages/flask/app.py", line 2292, in wsgi_app
    response = self.full_dispatch_request()
  File "/home/v1b3m/flask/microblog/venv/lib/python3.6/site-packages/flask/app.py", line 1815, in full_dispatch_request
    rv = self.handle_user_exception(e)
  File "/home/v1b3m/flask/microblog/venv/lib/python3.6/site-packages/flask/app.py", line 1718, in handle_user_exception
    reraise(exc_type, exc_value, tb)
  File "/home/v1b3m/flask/microblog/venv/lib/python3.6/site-packages/flask/_compat.py", line 35, in reraise
    raise value
  File "/home/v1b3m/flask/microblog/venv/lib/python3.6/site-packages/flask/app.py", line 1813, in full_dispatch_request
    rv = self.dispatch_request()
  File "/home/v1b3m/flask/microblog/venv/lib/python3.6/site-packages/flask/app.py", line 1799, in dispatch_request
    return self.view_functions[rule.endpoint](**req.view_args)
  File "/home/v1b3m/flask/microblog/app/routes.py", line 157, in reset_password_request
    send_password_reset_email(user)
  File "/home/v1b3m/flask/microblog/app/email.py", line 24, in send_password_reset_email
    user=user, token=token))
  File "/home/v1b3m/flask/microblog/app/email.py", line 14, in send_email
    Thread(target=send_async_email, arg=(app,msg)).start()
TypeError: __init__() got an unexpected keyword argument 'arg'
2018-10-03 18:41:14,396 INFO: Microblog startup [in /home/v1b3m/flask/microblog/app/__init__.py:47]
2018-10-03 22:02:10,812 INFO: Microblog startup [in /home/v1b3m/flask/microblog/app/__init__.py:47]
2018-10-03 22:04:40,034 INFO: Microblog startup [in /home/v1b3m/flask/microblog/app/__init__.py:47]
2018-10-04 11:06:28,309 INFO: Microblog startup [in /home/v1b3m/flask/microblog/app/__init__.py:47]
2018-10-04 11:12:49,753 INFO: Microblog startup [in /home/v1b3m/flask/microblog/app/__init__.py:49]
2018-10-04 11:15:08,693 INFO: Microblog startup [in /home/v1b3m/flask/microblog/app/__init__.py:49]
2018-10-04 11:16:01,306 INFO: Microblog startup [in /home/v1b3m/flask/microblog/app/__init__.py:49]
2018-10-04 11:27:42,085 INFO: Microblog startup [in /home/v1b3m/flask/microblog/app/__init__.py:52]
