2018-10-03 17:12:52,120 ERROR: Exception on /login [GET] [in /home/v1b3m/flask/microblog/venv/lib/python3.6/site-packages/flask/app.py:1761]
Traceback (most recent call last):
  File "/home/v1b3m/flask/microblog/venv/lib/python3.6/site-packages/flask/app.py", line 2292, in wsgi_app
    response = self.full_dispatch_request()
  File "/home/v1b3m/flask/microblog/venv/lib/python3.6/site-packages/flask/app.py", line 1815, in full_dispatch_request
    rv = self.handle_user_exception(e)
  File "/home/v1b3m/flask/microblog/venv/lib/python3.6/site-packages/flask/app.py", line 1718, in handle_user_exception
    reraise(exc_type, exc_value, tb)
  File "/home/v1b3m/flask/microblog/venv/lib/python3.6/site-packages/flask/_compat.py", line 35, in reraise
    raise value
  File "/home/v1b3m/flask/microblog/venv/lib/python3.6/site-packages/flask/app.py", line 1813, in full_dispatch_request
    rv = self.dispatch_request()
  File "/home/v1b3m/flask/microblog/venv/lib/python3.6/site-packages/flask/app.py", line 1799, in dispatch_request
    return self.view_functions[rule.endpoint](**req.view_args)
  File "/home/v1b3m/flask/microblog/app/routes.py", line 54, in login
    return render_template('login.html', title='Sign In', form=form)
  File "/home/v1b3m/flask/microblog/venv/lib/python3.6/site-packages/flask/templating.py", line 135, in render_template
    context, ctx.app)
  File "/home/v1b3m/flask/microblog/venv/lib/python3.6/site-packages/flask/templating.py", line 117, in _render
    rv = template.render(context)
  File "/home/v1b3m/flask/microblog/venv/lib/python3.6/site-packages/jinja2/asyncsupport.py", line 76, in render
    return original_render(self, *args, **kwargs)
  File "/home/v1b3m/flask/microblog/venv/lib/python3.6/site-packages/jinja2/environment.py", line 1008, in render
    return self.environment.handle_exception(exc_info, True)
  File "/home/v1b3m/flask/microblog/venv/lib/python3.6/site-packages/jinja2/environment.py", line 780, in handle_exception
    reraise(exc_type, exc_value, tb)
  File "/home/v1b3m/flask/microblog/venv/lib/python3.6/site-packages/jinja2/_compat.py", line 37, in reraise
    raise value.with_traceback(tb)
  File "/home/v1b3m/flask/microblog/app/templates/login.html", line 1, in top-level template code
    {% extends "base.html" %}
  File "/home/v1b3m/flask/microblog/app/templates/base.html", line 35, in top-level template code
    {% block content %}{% endblock %}
  File "/home/v1b3m/flask/microblog/app/templates/login.html", line 23, in block "content"
    <a href="{{ url_for('reset_password_request') }}">Click to Reset It</a>
  File "/home/v1b3m/flask/microblog/venv/lib/python3.6/site-packages/flask/helpers.py", line 356, in url_for
    return appctx.app.handle_url_build_error(error, endpoint, values)
  File "/home/v1b3m/flask/microblog/venv/lib/python3.6/site-packages/flask/app.py", line 2061, in handle_url_build_error
    reraise(exc_type, exc_value, tb)
  File "/home/v1b3m/flask/microblog/venv/lib/python3.6/site-packages/flask/_compat.py", line 35, in reraise
    raise value
  File "/home/v1b3m/flask/microblog/venv/lib/python3.6/site-packages/flask/helpers.py", line 345, in url_for
    force_external=external)
  File "/home/v1b3m/flask/microblog/venv/lib/python3.6/site-packages/werkzeug/routing.py", line 1776, in build
    raise BuildError(endpoint, values, method, self)
werkzeug.routing.BuildError: Could not build url for endpoint 'reset_password_request'. Did you mean 'edit_profile' instead?
2018-10-03 18:18:59,388 INFO: Microblog startup [in /home/v1b3m/flask/microblog/app/__init__.py:47]
2018-10-03 18:22:02,679 ERROR: Exception on /reset_password_request [GET] [in /home/v1b3m/flask/microblog/venv/lib/python3.6/site-packages/flask/app.py:1761]
Traceback (most recent call last):
  File "/home/v1b3m/flask/microblog/venv/lib/python3.6/site-packages/flask/app.py", line 2292, in wsgi_app
    response = self.full_dispatch_request()
  File "/home/v1b3m/flask/microblog/venv/lib/python3.6/site-packages/flask/app.py", line 1816, in full_dispatch_request
    return self.finalize_request(rv)
  File "/home/v1b3m/flask/microblog/venv/lib/python3.6/site-packages/flask/app.py", line 1831, in finalize_request
    response = self.make_response(rv)
  File "/home/v1b3m/flask/microblog/venv/lib/python3.6/site-packages/flask/app.py", line 1957, in make_response
    'The view function did not return a valid response. The'
TypeError: The view function did not return a valid response. The function either returned None or ended without a return statement.
2018-10-03 18:25:05,203 ERROR: Exception on /reset_password_request [GET] [in /home/v1b3m/flask/microblog/venv/lib/python3.6/site-packages/flask/app.py:1761]
Traceback (most recent call last):
  File "/home/v1b3m/flask/microblog/venv/lib/python3.6/site-packages/flask/app.py", line 2292, in wsgi_app
    response = self.full_dispatch_request()
  File "/home/v1b3m/flask/microblog/venv/lib/python3.6/site-packages/flask/app.py", line 1816, in full_dispatch_request
    return self.finalize_request(rv)
  File "/home/v1b3m/flask/microblog/venv/lib/python3.6/site-packages/flask/app.py", line 1831, in finalize_request
    response = self.make_response(rv)
  File "/home/v1b3m/flask/microblog/venv/lib/python3.6/site-packages/flask/app.py", line 1957, in make_response
    'The view function did not return a valid response. The'
TypeError: The view function did not return a valid response. The function either returned None or ended without a return statement.
2018-10-03 18:25:30,836 INFO: Microblog startup [in /home/v1b3m/flask/microblog/app/__init__.py:47]
2018-10-03 18:25:52,692 ERROR: Exception on /reset_password_request [POST] [in /home/v1b3m/flask/microblog/venv/lib/python3.6/site-packages/flask/app.py:1761]
Traceback (most recent call last):
  File "/home/v1b3m/flask/microblog/venv/lib/python3.6/site-packages/flask/app.py", line 2292, in wsgi_app
    response = self.full_dispatch_request()
  File "/home/v1b3m/flask/microblog/venv/lib/python3.6/site-packages/flask/app.py", line 1815, in full_dispatch_request
    rv = self.handle_user_exception(e)
  File "/home/v1b3m/flask/microblog/venv/lib/python3.6/site-packages/flask/app.py", line 1718, in handle_user_exception
    reraise(exc_type, exc_value, tb)
  File "/home/v1b3m/flask/microblog/venv/lib/python3.6/site-packages/flask/_compat.py", line 35, in reraise
    raise value
  File "/home/v1b3m/flask/microblog/venv/lib/python3.6/site-packages/flask/app.py", line 1813, in full_dispatch_request
    rv = self.dispatch_request()
  File "/home/v1b3m/flask/microblog/venv/lib/python3.6/site-packages/flask/app.py", line 1799, in dispatch_request
    return self.view_functions[rule.endpoint](**req.view_args)
  File "/home/v1b3m/flask/microblog/app/routes.py", line 157, in reset_password_request
    send_password_reset_email(user)
  File "/home/v1b3m/flask/microblog/app/email.py", line 11, in send_password_reset_email
    token = user.get_reset_password_token()
  File "/home/v1b3m/flask/microblog/app/models.py", line 68, in get_reset_password_token
    app.config['SECRET_KEY'],algorith='HS256').decode('utf-8')
TypeError: encode() got an unexpected keyword argument 'algorith'
2018-10-03 18:26:57,629 INFO: Microblog startup [in /home/v1b3m/flask/microblog/app/__init__.py:47]
2018-10-03 18:27:02,194 ERROR: Exception on /reset_password_request [POST] [in /home/v1b3m/flask/microblog/venv/lib/python3.6/site-packages/flask/app.py:1761]
Traceback (most recent call last):
  File "/home/v1b3m/flask/microblog/venv/lib/python3.6/site-packages/flask/app.py", line 2292, in wsgi_app
    response = self.full_dispatch_request()
  File "/home/v1b3m/flask/microblog/venv/lib/python3.6/site-packages/flask/app.py", line 1815, in full_dispatch_request
    rv = self.handle_user_exception(e)
  File "/home/v1b3m/flask/microblog/venv/lib/python3.6/site-packages/flask/app.py", line 1718, in handle_user_exception
    reraise(exc_type, exc_value, tb)
  File "/home/v1b3m/flask/microblog/venv/lib/python3.6/site-packages/flask/_compat.py", line 35, in reraise
    raise value
  File "/home/v1b3m/flask/microblog/venv/lib/python3.6/site-packages/flask/app.py", line 1813, in full_dispatch_request
    rv = self.dispatch_request()
  File "/home/v1b3m/flask/microblog/venv/lib/python3.6/site-packages/flask/app.py", line 1799, in dispatch_request
    return self.view_functions[rule.endpoint](**req.view_args)
  File "/home/v1b3m/flask/microblog/app/routes.py", line 157, in reset_password_request
    send_password_reset_email(user)
  File "/home/v1b3m/flask/microblog/app/email.py", line 13, in send_password_reset_email
    sender=app.config['ADMINS'][0],
NameError: name 'app' is not defined
2018-10-03 18:29:48,014 INFO: Microblog startup [in /home/v1b3m/flask/microblog/app/__init__.py:47]
2018-10-03 18:29:53,137 ERROR: Exception on /reset_password_request [POST] [in /home/v1b3m/flask/microblog/venv/lib/python3.6/site-packages/flask/app.py:1761]
Traceback (most recent call last):
  File "/home/v1b3m/flask/microblog/venv/lib/python3.6/site-packages/flask/app.py", line 2292, in wsgi_app
    response = self.full_dispatch_request()
  File "/home/v1b3m/flask/microblog/venv/lib/python3.6/site-packages/flask/app.py", line 1815, in full_dispatch_request
    rv = self.handle_user_exception(e)
  File "/home/v1b3m/flask/microblog/venv/lib/python3.6/site-packages/flask/app.py", line 1718, in handle_user_exception
    reraise(exc_type, exc_value, tb)
  File "/home/v1b3m/flask/microblog/venv/lib/python3.6/site-packages/flask/_compat.py", line 35, in reraise
    raise value
  File "/home/v1b3m/flask/microblog/venv/lib/python3.6/site-packages/flask/app.py", line 1813, in full_dispatch_request
    rv = self.dispatch_request()
  File "/home/v1b3m/flask/microblog/venv/lib/python3.6/site-packages/flask/app.py", line 1799, in dispatch_request
    return self.view_functions[rule.endpoint](**req.view_args)
  File "/home/v1b3m/flask/microblog/app/routes.py", line 157, in reset_password_request
    send_password_reset_email(user)
  File "/home/v1b3m/flask/microblog/app/email.py", line 13, in send_password_reset_email
    sender=app.config['ADMINS'][0],
NameError: name 'app' is not defined
